2024-03-14T20:11:26 {"cpu": 0.80712890625, "cpu_total": 4, "cpu_usage": 0.2017822265625, "memory": 6077.0, "memory_total": 15698.0, "memory_usage": 0.3871193782647471, "pipeline_run_id": 8, "pipeline_schedule_id": 2, "pipeline_uuid": "green_taxi_etl", "hostname": "c558996a83e4", "level": "INFO", "message": "Pipeline green_taxi_etl for run 8 in schedule 2 is alive.", "timestamp": 1710447086.767079, "uuid": "d9e0227d914f40fd9c12333bd339f3d0"}
2024-03-14T20:11:27 {"cpu": 0.80712890625, "cpu_total": 4, "cpu_usage": 0.2017822265625, "memory": 6238.0, "memory_total": 15698.0, "memory_usage": 0.3973754618422729, "pipeline_run_id": 8, "pipeline_schedule_id": 2, "pipeline_uuid": "green_taxi_etl", "hostname": "c558996a83e4", "level": "INFO", "message": "Pipeline green_taxi_etl for run 8 in schedule 2 is alive.", "timestamp": 1710447087.139568, "uuid": "ebeb922ce5ad4ce0b808e778f8bb35e8"}
2024-03-14T20:11:27 {"block_run_id": 40, "block_uuid": "load_green_taxi_data", "pipeline_run_id": 8, "pipeline_schedule_id": 2, "pipeline_uuid": "green_taxi_etl", "hostname": "c558996a83e4", "level": "INFO", "message": "Execute PipelineRun 8, BlockRun 40: pipeline green_taxi_etl block load_green_taxi_data", "timestamp": 1710447087.314042, "uuid": "6479bcfb4a944f86a1f8670c51758fb0"}
2024-03-14T20:11:32 {"block_run_id": 40, "block_uuid": "load_green_taxi_data", "pipeline_run_id": 8, "pipeline_schedule_id": 2, "pipeline_uuid": "green_taxi_etl", "hostname": "c558996a83e4", "level": "EXCEPTION", "message": "BlockRun 40 (block_uuid: load_green_taxi_data) failed.", "timestamp": 1710447092.48697, "uuid": "29664312f44043c98bb0737fcac06ae0", "error": ["Traceback (most recent call last):\n  File \"/usr/local/lib/python3.10/urllib/request.py\", line 1348, in do_open\n    h.request(req.get_method(), req.selector, req.data, headers,\n  File \"/usr/local/lib/python3.10/http/client.py\", line 1283, in request\n    self._send_request(method, url, body, headers, encode_chunked)\n  File \"/usr/local/lib/python3.10/http/client.py\", line 1329, in _send_request\n    self.endheaders(body, encode_chunked=encode_chunked)\n  File \"/usr/local/lib/python3.10/http/client.py\", line 1278, in endheaders\n    self._send_output(message_body, encode_chunked=encode_chunked)\n  File \"/usr/local/lib/python3.10/http/client.py\", line 1038, in _send_output\n    self.send(msg)\n  File \"/usr/local/lib/python3.10/http/client.py\", line 976, in send\n    self.connect()\n  File \"/usr/local/lib/python3.10/http/client.py\", line 1448, in connect\n    super().connect()\n  File \"/usr/local/lib/python3.10/http/client.py\", line 942, in connect\n    self.sock = self._create_connection(\n  File \"/usr/local/lib/python3.10/socket.py\", line 824, in create_connection\n    for res in getaddrinfo(host, port, 0, SOCK_STREAM):\n  File \"/usr/local/lib/python3.10/socket.py\", line 955, in getaddrinfo\n    for res in _socket.getaddrinfo(host, port, family, type, proto, flags):\nsocket.gaierror: [Errno -5] No address associated with hostname\n\nDuring handling of the above exception, another exception occurred:\n\nTraceback (most recent call last):\n  File \"/usr/local/lib/python3.10/site-packages/mage_ai/data_preparation/executors/block_executor.py\", line 613, in execute\n    result = __execute_with_retry()\n  File \"/usr/local/lib/python3.10/site-packages/mage_ai/shared/retry.py\", line 54, in retry_func\n    raise e\n  File \"/usr/local/lib/python3.10/site-packages/mage_ai/shared/retry.py\", line 38, in retry_func\n    return func(*args, **kwargs)\n  File \"/usr/local/lib/python3.10/site-packages/mage_ai/data_preparation/executors/block_executor.py\", line 588, in __execute_with_retry\n    return self._execute(\n  File \"/usr/local/lib/python3.10/site-packages/mage_ai/data_preparation/executors/block_executor.py\", line 1077, in _execute\n    result = self.block.execute_sync(\n  File \"/usr/local/lib/python3.10/site-packages/mage_ai/data_preparation/models/block/__init__.py\", line 1312, in execute_sync\n    raise err\n  File \"/usr/local/lib/python3.10/site-packages/mage_ai/data_preparation/models/block/__init__.py\", line 1221, in execute_sync\n    output = self.execute_block(\n  File \"/usr/local/lib/python3.10/site-packages/mage_ai/data_preparation/models/block/__init__.py\", line 1527, in execute_block\n    outputs = self._execute_block(\n  File \"/usr/local/lib/python3.10/site-packages/mage_ai/data_preparation/models/block/__init__.py\", line 1683, in _execute_block\n    outputs = self.execute_block_function(\n  File \"/usr/local/lib/python3.10/site-packages/mage_ai/data_preparation/models/block/__init__.py\", line 1722, in execute_block_function\n    output = block_function_updated(*input_vars, **global_vars)\n  File \"<string>\", line 51, in load_data\n  File \"/usr/local/lib/python3.10/site-packages/pandas/util/_decorators.py\", line 211, in wrapper\n    return func(*args, **kwargs)\n  File \"/usr/local/lib/python3.10/site-packages/pandas/util/_decorators.py\", line 331, in wrapper\n    return func(*args, **kwargs)\n  File \"/usr/local/lib/python3.10/site-packages/pandas/io/parsers/readers.py\", line 950, in read_csv\n    return _read(filepath_or_buffer, kwds)\n  File \"/usr/local/lib/python3.10/site-packages/pandas/io/parsers/readers.py\", line 605, in _read\n    parser = TextFileReader(filepath_or_buffer, **kwds)\n  File \"/usr/local/lib/python3.10/site-packages/pandas/io/parsers/readers.py\", line 1442, in __init__\n    self._engine = self._make_engine(f, self.engine)\n  File \"/usr/local/lib/python3.10/site-packages/pandas/io/parsers/readers.py\", line 1735, in _make_engine\n    self.handles = get_handle(\n  File \"/usr/local/lib/python3.10/site-packages/pandas/io/common.py\", line 713, in get_handle\n    ioargs = _get_filepath_or_buffer(\n  File \"/usr/local/lib/python3.10/site-packages/pandas/io/common.py\", line 363, in _get_filepath_or_buffer\n    with urlopen(req_info) as req:\n  File \"/usr/local/lib/python3.10/site-packages/pandas/io/common.py\", line 265, in urlopen\n    return urllib.request.urlopen(*args, **kwargs)\n  File \"/usr/local/lib/python3.10/urllib/request.py\", line 216, in urlopen\n    return opener.open(url, data, timeout)\n  File \"/usr/local/lib/python3.10/urllib/request.py\", line 519, in open\n    response = self._open(req, data)\n  File \"/usr/local/lib/python3.10/urllib/request.py\", line 536, in _open\n    result = self._call_chain(self.handle_open, protocol, protocol +\n  File \"/usr/local/lib/python3.10/urllib/request.py\", line 496, in _call_chain\n    result = func(*args)\n  File \"/usr/local/lib/python3.10/urllib/request.py\", line 1391, in https_open\n    return self.do_open(http.client.HTTPSConnection, req,\n  File \"/usr/local/lib/python3.10/urllib/request.py\", line 1351, in do_open\n    raise URLError(err)\nurllib.error.URLError: <urlopen error [Errno -5] No address associated with hostname>\n"], "error_stack": [["  File \"/usr/local/bin/mage\", line 8, in <module>\n    sys.exit(app())\n", "  File \"/usr/local/lib/python3.10/site-packages/typer/main.py\", line 311, in __call__\n    return get_command(self)(*args, **kwargs)\n", "  File \"/usr/local/lib/python3.10/site-packages/click/core.py\", line 1130, in __call__\n    return self.main(*args, **kwargs)\n", "  File \"/usr/local/lib/python3.10/site-packages/typer/core.py\", line 778, in main\n    return _main(\n", "  File \"/usr/local/lib/python3.10/site-packages/typer/core.py\", line 216, in _main\n    rv = self.invoke(ctx)\n", "  File \"/usr/local/lib/python3.10/site-packages/click/core.py\", line 1657, in invoke\n    return _process_result(sub_ctx.command.invoke(sub_ctx))\n", "  File \"/usr/local/lib/python3.10/site-packages/click/core.py\", line 1404, in invoke\n    return ctx.invoke(self.callback, **ctx.params)\n", "  File \"/usr/local/lib/python3.10/site-packages/click/core.py\", line 760, in invoke\n    return __callback(*args, **kwargs)\n", "  File \"/usr/local/lib/python3.10/site-packages/typer/main.py\", line 683, in wrapper\n    return callback(**use_params)  # type: ignore\n", "  File \"/usr/local/lib/python3.10/site-packages/mage_ai/cli/main.py\", line 163, in start\n    start_server(\n", "  File \"/usr/local/lib/python3.10/site-packages/mage_ai/server/server.py\", line 659, in start_server\n    scheduler_manager.start_scheduler()\n", "  File \"/usr/local/lib/python3.10/site-packages/mage_ai/server/scheduler_manager.py\", line 87, in start_scheduler\n    proc.start()\n", "  File \"/usr/local/lib/python3.10/multiprocessing/process.py\", line 121, in start\n    self._popen = self._Popen(self)\n", "  File \"/usr/local/lib/python3.10/multiprocessing/context.py\", line 224, in _Popen\n    return _default_context.get_context().Process._Popen(process_obj)\n", "  File \"/usr/local/lib/python3.10/multiprocessing/context.py\", line 281, in _Popen\n    return Popen(process_obj)\n", "  File \"/usr/local/lib/python3.10/multiprocessing/popen_fork.py\", line 19, in __init__\n    self._launch(process_obj)\n", "  File \"/usr/local/lib/python3.10/multiprocessing/popen_fork.py\", line 71, in _launch\n    code = process_obj._bootstrap(parent_sentinel=child_r)\n", "  File \"/usr/local/lib/python3.10/multiprocessing/process.py\", line 314, in _bootstrap\n    self.run()\n", "  File \"/usr/local/lib/python3.10/multiprocessing/process.py\", line 108, in run\n    self._target(*self._args, **self._kwargs)\n", "  File \"/usr/local/lib/python3.10/site-packages/mage_ai/orchestration/db/process.py\", line 15, in start_session_and_run\n    results = target(*args)\n", "  File \"/usr/local/lib/python3.10/site-packages/mage_ai/server/scheduler_manager.py\", line 50, in run_scheduler\n    LoopTimeTrigger().start()\n", "  File \"/usr/local/lib/python3.10/site-packages/mage_ai/orchestration/triggers/loop_time_trigger.py\", line 14, in start\n    self.run()\n", "  File \"/usr/local/lib/python3.10/site-packages/mage_ai/orchestration/triggers/time_trigger.py\", line 11, in run\n    schedule_all()\n", "  File \"/usr/local/lib/python3.10/site-packages/mage_ai/orchestration/pipeline_scheduler_original.py\", line 1575, in schedule_all\n    PipelineScheduler(r).start()\n", "  File \"/usr/local/lib/python3.10/site-packages/mage_ai/orchestration/db/__init__.py\", line 149, in func_with_rollback\n    return func(*args, **kwargs)\n", "  File \"/usr/local/lib/python3.10/site-packages/mage_ai/orchestration/pipeline_scheduler_original.py\", line 182, in start\n    self.schedule()\n", "  File \"/usr/local/lib/python3.10/site-packages/mage_ai/orchestration/db/__init__.py\", line 149, in func_with_rollback\n    return func(*args, **kwargs)\n", "  File \"/usr/local/lib/python3.10/site-packages/mage_ai/orchestration/pipeline_scheduler_original.py\", line 319, in schedule\n    self.__schedule_blocks(block_runs)\n", "  File \"/usr/local/lib/python3.10/site-packages/mage_ai/orchestration/pipeline_scheduler_original.py\", line 584, in __schedule_blocks\n    job_manager.add_job(\n", "  File \"/usr/local/lib/python3.10/site-packages/mage_ai/orchestration/job_manager.py\", line 27, in add_job\n    self.queue.enqueue(job_id, target, *args, **kwargs)\n", "  File \"/usr/local/lib/python3.10/site-packages/mage_ai/orchestration/queue/process_queue.py\", line 108, in enqueue\n    self.start_worker_pool()\n", "  File \"/usr/local/lib/python3.10/site-packages/mage_ai/orchestration/queue/process_queue.py\", line 183, in start_worker_pool\n    self.worker_pool_proc.start()\n", "  File \"/usr/local/lib/python3.10/multiprocessing/process.py\", line 121, in start\n    self._popen = self._Popen(self)\n", "  File \"/usr/local/lib/python3.10/multiprocessing/context.py\", line 224, in _Popen\n    return _default_context.get_context().Process._Popen(process_obj)\n", "  File \"/usr/local/lib/python3.10/multiprocessing/context.py\", line 281, in _Popen\n    return Popen(process_obj)\n", "  File \"/usr/local/lib/python3.10/multiprocessing/popen_fork.py\", line 19, in __init__\n    self._launch(process_obj)\n", "  File \"/usr/local/lib/python3.10/multiprocessing/popen_fork.py\", line 71, in _launch\n    code = process_obj._bootstrap(parent_sentinel=child_r)\n", "  File \"/usr/local/lib/python3.10/multiprocessing/process.py\", line 314, in _bootstrap\n    self.run()\n", "  File \"/usr/local/lib/python3.10/multiprocessing/process.py\", line 108, in run\n    self._target(*self._args, **self._kwargs)\n", "  File \"/usr/local/lib/python3.10/site-packages/mage_ai/orchestration/queue/process_queue.py\", line 288, in poll_job_and_execute\n    worker.start()\n", "  File \"/usr/local/lib/python3.10/multiprocessing/process.py\", line 121, in start\n    self._popen = self._Popen(self)\n", "  File \"/usr/local/lib/python3.10/multiprocessing/context.py\", line 224, in _Popen\n    return _default_context.get_context().Process._Popen(process_obj)\n", "  File \"/usr/local/lib/python3.10/multiprocessing/context.py\", line 281, in _Popen\n    return Popen(process_obj)\n", "  File \"/usr/local/lib/python3.10/multiprocessing/popen_fork.py\", line 19, in __init__\n    self._launch(process_obj)\n", "  File \"/usr/local/lib/python3.10/multiprocessing/popen_fork.py\", line 71, in _launch\n    code = process_obj._bootstrap(parent_sentinel=child_r)\n", "  File \"/usr/local/lib/python3.10/multiprocessing/process.py\", line 314, in _bootstrap\n    self.run()\n", "  File \"/usr/local/lib/python3.10/site-packages/newrelic/api/background_task.py\", line 117, in wrapper\n    return wrapped(*args, **kwargs)\n", "  File \"/usr/local/lib/python3.10/site-packages/mage_ai/orchestration/queue/process_queue.py\", line 253, in run\n    start_session_and_run(args[1], *args[2], **args[3])\n", "  File \"/usr/local/lib/python3.10/site-packages/mage_ai/orchestration/db/process.py\", line 15, in start_session_and_run\n    results = target(*args)\n", "  File \"/usr/local/lib/python3.10/site-packages/mage_ai/orchestration/pipeline_scheduler_original.py\", line 1128, in run_block\n    return ExecutorFactory.get_block_executor(\n", "  File \"/usr/local/lib/python3.10/site-packages/mage_ai/data_preparation/executors/block_executor.py\", line 641, in execute\n    on_failure(\n", "  File \"/usr/local/lib/python3.10/site-packages/mage_ai/orchestration/db/__init__.py\", line 149, in func_with_rollback\n    return func(*args, **kwargs)\n", "  File \"/usr/local/lib/python3.10/site-packages/mage_ai/orchestration/pipeline_scheduler_original.py\", line 415, in on_block_failure\n    self.logger.exception(\n", "  File \"/usr/local/lib/python3.10/site-packages/mage_ai/data_preparation/logging/logger.py\", line 30, in exception\n    self.__send_message('exception', message, **kwargs)\n", "  File \"/usr/local/lib/python3.10/site-packages/mage_ai/data_preparation/logging/logger.py\", line 59, in __send_message\n    data['error_stack'] = traceback.format_stack(),\n"]], "error_stacktrace": ["<urlopen error [Errno -5] No address associated with hostname>"]}
Traceback (most recent call last):
  File "/usr/local/lib/python3.10/urllib/request.py", line 1348, in do_open
    h.request(req.get_method(), req.selector, req.data, headers,
  File "/usr/local/lib/python3.10/http/client.py", line 1283, in request
    self._send_request(method, url, body, headers, encode_chunked)
  File "/usr/local/lib/python3.10/http/client.py", line 1329, in _send_request
    self.endheaders(body, encode_chunked=encode_chunked)
  File "/usr/local/lib/python3.10/http/client.py", line 1278, in endheaders
    self._send_output(message_body, encode_chunked=encode_chunked)
  File "/usr/local/lib/python3.10/http/client.py", line 1038, in _send_output
    self.send(msg)
  File "/usr/local/lib/python3.10/http/client.py", line 976, in send
    self.connect()
  File "/usr/local/lib/python3.10/http/client.py", line 1448, in connect
    super().connect()
  File "/usr/local/lib/python3.10/http/client.py", line 942, in connect
    self.sock = self._create_connection(
  File "/usr/local/lib/python3.10/socket.py", line 824, in create_connection
    for res in getaddrinfo(host, port, 0, SOCK_STREAM):
  File "/usr/local/lib/python3.10/socket.py", line 955, in getaddrinfo
    for res in _socket.getaddrinfo(host, port, family, type, proto, flags):
socket.gaierror: [Errno -5] No address associated with hostname

During handling of the above exception, another exception occurred:

Traceback (most recent call last):
  File "/usr/local/lib/python3.10/site-packages/mage_ai/data_preparation/executors/block_executor.py", line 613, in execute
    result = __execute_with_retry()
  File "/usr/local/lib/python3.10/site-packages/mage_ai/shared/retry.py", line 54, in retry_func
    raise e
  File "/usr/local/lib/python3.10/site-packages/mage_ai/shared/retry.py", line 38, in retry_func
    return func(*args, **kwargs)
  File "/usr/local/lib/python3.10/site-packages/mage_ai/data_preparation/executors/block_executor.py", line 588, in __execute_with_retry
    return self._execute(
  File "/usr/local/lib/python3.10/site-packages/mage_ai/data_preparation/executors/block_executor.py", line 1077, in _execute
    result = self.block.execute_sync(
  File "/usr/local/lib/python3.10/site-packages/mage_ai/data_preparation/models/block/__init__.py", line 1312, in execute_sync
    raise err
  File "/usr/local/lib/python3.10/site-packages/mage_ai/data_preparation/models/block/__init__.py", line 1221, in execute_sync
    output = self.execute_block(
  File "/usr/local/lib/python3.10/site-packages/mage_ai/data_preparation/models/block/__init__.py", line 1527, in execute_block
    outputs = self._execute_block(
  File "/usr/local/lib/python3.10/site-packages/mage_ai/data_preparation/models/block/__init__.py", line 1683, in _execute_block
    outputs = self.execute_block_function(
  File "/usr/local/lib/python3.10/site-packages/mage_ai/data_preparation/models/block/__init__.py", line 1722, in execute_block_function
    output = block_function_updated(*input_vars, **global_vars)
  File "<string>", line 51, in load_data
  File "/usr/local/lib/python3.10/site-packages/pandas/util/_decorators.py", line 211, in wrapper
    return func(*args, **kwargs)
  File "/usr/local/lib/python3.10/site-packages/pandas/util/_decorators.py", line 331, in wrapper
    return func(*args, **kwargs)
  File "/usr/local/lib/python3.10/site-packages/pandas/io/parsers/readers.py", line 950, in read_csv
    return _read(filepath_or_buffer, kwds)
  File "/usr/local/lib/python3.10/site-packages/pandas/io/parsers/readers.py", line 605, in _read
    parser = TextFileReader(filepath_or_buffer, **kwds)
  File "/usr/local/lib/python3.10/site-packages/pandas/io/parsers/readers.py", line 1442, in __init__
    self._engine = self._make_engine(f, self.engine)
  File "/usr/local/lib/python3.10/site-packages/pandas/io/parsers/readers.py", line 1735, in _make_engine
    self.handles = get_handle(
  File "/usr/local/lib/python3.10/site-packages/pandas/io/common.py", line 713, in get_handle
    ioargs = _get_filepath_or_buffer(
  File "/usr/local/lib/python3.10/site-packages/pandas/io/common.py", line 363, in _get_filepath_or_buffer
    with urlopen(req_info) as req:
  File "/usr/local/lib/python3.10/site-packages/pandas/io/common.py", line 265, in urlopen
    return urllib.request.urlopen(*args, **kwargs)
  File "/usr/local/lib/python3.10/urllib/request.py", line 216, in urlopen
    return opener.open(url, data, timeout)
  File "/usr/local/lib/python3.10/urllib/request.py", line 519, in open
    response = self._open(req, data)
  File "/usr/local/lib/python3.10/urllib/request.py", line 536, in _open
    result = self._call_chain(self.handle_open, protocol, protocol +
  File "/usr/local/lib/python3.10/urllib/request.py", line 496, in _call_chain
    result = func(*args)
  File "/usr/local/lib/python3.10/urllib/request.py", line 1391, in https_open
    return self.do_open(http.client.HTTPSConnection, req,
  File "/usr/local/lib/python3.10/urllib/request.py", line 1351, in do_open
    raise URLError(err)
urllib.error.URLError: <urlopen error [Errno -5] No address associated with hostname>
2024-03-14T20:11:36 {"cpu": 0.81005859375, "cpu_total": 4, "cpu_usage": 0.2025146484375, "memory": 6197.0, "memory_total": 15698.0, "memory_usage": 0.39476366416103964, "pipeline_run_id": 8, "pipeline_schedule_id": 2, "pipeline_uuid": "green_taxi_etl", "hostname": "c558996a83e4", "level": "INFO", "message": "Pipeline green_taxi_etl for run 8 in schedule 2 is alive.", "timestamp": 1710447096.416522, "uuid": "87044277fe5547a491c1d80f22b4585a"}
